<?xml version="1.0" ?>
<!-- =================================================================================== -->
<!-- |    This document was autogenerated by xacro from src/pacote_de_exemplos/urdf/myfirstrobot.urdf.xacro | -->
<!-- |    EDITING THIS FILE BY HAND IS NOT RECOMMENDED                                 | -->
<!-- =================================================================================== -->
<robot name="robot">
  <material name="Cyan">
    <color rgba="0 1.0 1.0 1.0"/>
  </material>
  <!-- Robot -->
  <!-- link: base_footprint -->
  <link name="base_footprint"/>
  <!-- joint: base_footprint -> base -->
  <joint name="joint_base_footprint_to_base" type="fixed">
    <origin rpy="0 0 0" xyz="0 0 0.39999999999999997"/>
    <parent link="base_footprint"/>
    <child link="base_link"/>
  </joint>
  <!-- link: base -->
  <link name="base_link">
    <visual>
      <origin rpy="0 0 0" xyz="0 0 0"/>
      <geometry>
        <cylinder length="0.6" radius="0.19999999999999998"/>
      </geometry>
      <material name="Cyan"/>
    </visual>
    <collision>
      <origin rpy="0 0 0" xyz="0 0 0"/>
      <geometry>
        <cylinder length="0.6" radius="0.19999999999999998"/>
      </geometry>
    </collision>
    <inertial>
      <mass value="3.5"/>
      <inertia ixx="0.13999999999999999" ixy="0.0" ixz="0.0" iyy="0.13999999999999999" iyz="0.0" izz="0.06999999999999999"/>
    </inertial>
  </link>
  <joint name="base_to_laser" type="fixed">
    <origin rpy="0 0 0" xyz="0 0 -0.2"/>
    <parent link="base_link"/>
    <child link="base_scan"/>
  </joint>
  <link name="base_scan">
  </link>
  <!-- link: head -->
  <link name="head">
    <visual>
      <origin rpy="0 0 0" xyz="0 0 0"/>
      <geometry>
        <sphere radius="0.19999999999999998"/>
      </geometry>
    </visual>
    <collision>
      <origin rpy="0 0 0" xyz="0 0 0"/>
      <geometry>
        <sphere radius="0.19999999999999998"/>
      </geometry>
    </collision>
    <inertial>
      <mass value="0.5"/>
      <inertia ixx="0.008" ixy="0.0" ixz="0.0" iyy="0.008" iyz="0.0" izz="0.008"/>
    </inertial>
  </link>
  <!-- link: head_box -->
  <link name="head_box">
    <visual>
      <origin rpy="0 0 0" xyz="0 0 0"/>
      <geometry>
        <box size="0.06666666666666667 0.06666666666666667 0.06666666666666667"/>
      </geometry>
      <material name="Cyan"/>
    </visual>
    <collision>
      <origin rpy="0 0 0" xyz="0 0 0"/>
      <geometry>
        <box size="0.06666666666666667 0.06666666666666667 0.06666666666666667"/>
      </geometry>
    </collision>
    <inertial>
      <mass value="0.005"/>
      <inertia ixx="3.7037037037037033e-06" ixy="0.0" ixz="0.0" iyy="3.7037037037037033e-06" iyz="0.0" izz="3.7037037037037033e-06"/>
    </inertial>
  </link>
  <!-- joint: base -> head -->
  <joint name="joint_base_link_to_head" type="revolute">
    <origin rpy="0 0 0" xyz="0 0 0.3"/>
    <parent link="base_link"/>
    <child link="head"/>
    <axis xyz="0 0 1"/>
    <limit effort="30" lower="-1.570796325" upper="1.570796325" velocity="0.5"/>
  </joint>
  <!-- joint: head -> head_box -->
  <joint name="joint_head_to_head_box" type="fixed">
    <origin rpy="0 0 0" xyz="0.12 0 0.15"/>
    <parent link="head"/>
    <child link="head_box"/>
  </joint>
  <!-- joint: parent -> leg -->
  <joint name="base_link_to_left_leg" type="fixed">
    <origin rpy="0 0 0" xyz="0  0.19999999999999998 -0.06"/>
    <parent link="base_link"/>
    <child link="left_leg"/>
  </joint>
  <!-- link: leg -->
  <link name="left_leg">
    <visual>
      <origin rpy="0 0 0" xyz="0 0 0"/>
      <geometry>
        <box size="0.19999999999999998 0.09999999999999999 0.6"/>
      </geometry>
      <material name="Cyan"/>
    </visual>
    <collision>
      <origin rpy="0 0 0" xyz="0 0 0"/>
      <geometry>
        <box size="0.19999999999999998 0.09999999999999999 0.6"/>
      </geometry>
    </collision>
    <inertial>
      <mass value="0.5"/>
      <inertia ixx="0.015416666666666665" ixy="0.0" ixz="0.0" iyy="0.016666666666666663" iyz="0.0" izz="0.002083333333333333"/>
    </inertial>
  </link>
  <!-- joint: leg -> leg_base -->
  <joint name="left_leg_to_left_leg_base" type="fixed">
    <origin rpy="0 0 0" xyz="0 0 -0.3"/>
    <parent link="left_leg"/>
    <child link="left_leg_base"/>
  </joint>
  <!-- link: leg_base -->
  <link name="left_leg_base">
    <visual>
      <origin rpy="0 0 0" xyz="0 0 0"/>
      <geometry>
        <box size="0.39999999999999997 0.09999999999999999 0.09999999999999999"/>
      </geometry>
      <material name="Cyan"/>
    </visual>
    <collision>
      <origin rpy="0 0 0" xyz="0 0 0"/>
      <geometry>
        <box size="0.39999999999999997 0.09999999999999999 0.09999999999999999"/>
      </geometry>
    </collision>
    <inertial>
      <mass value="1.5"/>
      <inertia ixx="0.0024999999999999996" ixy="0.0" ixz="0.0" iyy="0.021249999999999998" iyz="0.0" izz="0.021249999999999998"/>
    </inertial>
  </link>
  <!-- joint: parent_base -> wheel -->
  <joint name="left_leg_base_to_left_front_wheel" type="continuous">
    <origin rpy="-1.57 0 0" xyz="0.12 0 -0.06"/>
    <parent link="left_leg_base"/>
    <child link="left_front_wheel"/>
    <axis xyz="0 0 1"/>
  </joint>
  <!-- link: wheel -->
  <link name="left_front_wheel">
    <origin rpy="-1.570796325 0 0" xyz="0 0 0"/>
    <visual>
      <origin rpy="0 0 0" xyz="0 0 0"/>
      <geometry>
        <sphere radius="0.019999999999999997"/>
      </geometry>
    </visual>
    <collision>
      <origin rpy="0 0 0" xyz="0 0 0"/>
      <geometry>
        <sphere radius="0.019999999999999997"/>
      </geometry>
    </collision>
    <inertial>
      <mass value="0.5"/>
      <inertia ixx="7.999999999999997e-05" ixy="0.0" ixz="0.0" iyy="7.999999999999997e-05" iyz="0.0" izz="7.999999999999997e-05"/>
    </inertial>
  </link>
  <!-- joint: parent_base -> wheel -->
  <joint name="left_leg_base_to_left_center_wheel" type="continuous">
    <origin rpy="-1.57 0 0" xyz="0 0 -0.061"/>
    <parent link="left_leg_base"/>
    <child link="left_center_wheel"/>
    <axis xyz="0 0 1"/>
  </joint>
  <!-- link: wheel -->
  <link name="left_center_wheel">
    <origin rpy="-1.570796325 0 0" xyz="0 0 0"/>
    <visual>
      <origin rpy="0 0 0" xyz="0 0 0"/>
      <geometry>
        <sphere radius="0.019999999999999997"/>
      </geometry>
    </visual>
    <collision>
      <origin rpy="0 0 0" xyz="0 0 0"/>
      <geometry>
        <sphere radius="0.019999999999999997"/>
      </geometry>
    </collision>
    <inertial>
      <mass value="0.5"/>
      <inertia ixx="7.999999999999997e-05" ixy="0.0" ixz="0.0" iyy="7.999999999999997e-05" iyz="0.0" izz="7.999999999999997e-05"/>
    </inertial>
  </link>
  <!-- joint: parent_base -> wheel -->
  <joint name="left_leg_base_to_left_back_wheel" type="continuous">
    <origin rpy="-1.57 0 0" xyz="-0.12 0 -0.06"/>
    <parent link="left_leg_base"/>
    <child link="left_back_wheel"/>
    <axis xyz="0 0 1"/>
  </joint>
  <!-- link: wheel -->
  <link name="left_back_wheel">
    <origin rpy="-1.570796325 0 0" xyz="0 0 0"/>
    <visual>
      <origin rpy="0 0 0" xyz="0 0 0"/>
      <geometry>
        <sphere radius="0.019999999999999997"/>
      </geometry>
    </visual>
    <collision>
      <origin rpy="0 0 0" xyz="0 0 0"/>
      <geometry>
        <sphere radius="0.019999999999999997"/>
      </geometry>
    </collision>
    <inertial>
      <mass value="0.5"/>
      <inertia ixx="7.999999999999997e-05" ixy="0.0" ixz="0.0" iyy="7.999999999999997e-05" iyz="0.0" izz="7.999999999999997e-05"/>
    </inertial>
  </link>
  <!-- joint: parent -> leg -->
  <joint name="base_link_to_right_leg" type="fixed">
    <origin rpy="0 0 0" xyz="0 -0.19999999999999998 -0.06"/>
    <parent link="base_link"/>
    <child link="right_leg"/>
  </joint>
  <!-- link: leg -->
  <link name="right_leg">
    <visual>
      <origin rpy="0 0 0" xyz="0 0 0"/>
      <geometry>
        <box size="0.19999999999999998 0.09999999999999999 0.6"/>
      </geometry>
      <material name="Cyan"/>
    </visual>
    <collision>
      <origin rpy="0 0 0" xyz="0 0 0"/>
      <geometry>
        <box size="0.19999999999999998 0.09999999999999999 0.6"/>
      </geometry>
    </collision>
    <inertial>
      <mass value="0.5"/>
      <inertia ixx="0.015416666666666665" ixy="0.0" ixz="0.0" iyy="0.016666666666666663" iyz="0.0" izz="0.002083333333333333"/>
    </inertial>
  </link>
  <!-- joint: leg -> leg_base -->
  <joint name="right_leg_to_right_leg_base" type="fixed">
    <origin rpy="0 0 0" xyz="0 0 -0.3"/>
    <parent link="right_leg"/>
    <child link="right_leg_base"/>
  </joint>
  <!-- link: leg_base -->
  <link name="right_leg_base">
    <visual>
      <origin rpy="0 0 0" xyz="0 0 0"/>
      <geometry>
        <box size="0.39999999999999997 0.09999999999999999 0.09999999999999999"/>
      </geometry>
      <material name="Cyan"/>
    </visual>
    <collision>
      <origin rpy="0 0 0" xyz="0 0 0"/>
      <geometry>
        <box size="0.39999999999999997 0.09999999999999999 0.09999999999999999"/>
      </geometry>
    </collision>
    <inertial>
      <mass value="1.5"/>
      <inertia ixx="0.0024999999999999996" ixy="0.0" ixz="0.0" iyy="0.021249999999999998" iyz="0.0" izz="0.021249999999999998"/>
    </inertial>
  </link>
  <!-- joint: parent_base -> wheel -->
  <joint name="right_leg_base_to_right_front_wheel" type="continuous">
    <origin rpy="-1.57 0 0" xyz="0.12 0 -0.06"/>
    <parent link="right_leg_base"/>
    <child link="right_front_wheel"/>
    <axis xyz="0 0 1"/>
  </joint>
  <!-- link: wheel -->
  <link name="right_front_wheel">
    <origin rpy="-1.570796325 0 0" xyz="0 0 0"/>
    <visual>
      <origin rpy="0 0 0" xyz="0 0 0"/>
      <geometry>
        <sphere radius="0.019999999999999997"/>
      </geometry>
    </visual>
    <collision>
      <origin rpy="0 0 0" xyz="0 0 0"/>
      <geometry>
        <sphere radius="0.019999999999999997"/>
      </geometry>
    </collision>
    <inertial>
      <mass value="0.5"/>
      <inertia ixx="7.999999999999997e-05" ixy="0.0" ixz="0.0" iyy="7.999999999999997e-05" iyz="0.0" izz="7.999999999999997e-05"/>
    </inertial>
  </link>
  <!-- joint: parent_base -> wheel -->
  <joint name="right_leg_base_to_right_center_wheel" type="continuous">
    <origin rpy="-1.57 0 0" xyz="0 0 -0.061"/>
    <parent link="right_leg_base"/>
    <child link="right_center_wheel"/>
    <axis xyz="0 0 1"/>
  </joint>
  <!-- link: wheel -->
  <link name="right_center_wheel">
    <origin rpy="-1.570796325 0 0" xyz="0 0 0"/>
    <visual>
      <origin rpy="0 0 0" xyz="0 0 0"/>
      <geometry>
        <sphere radius="0.019999999999999997"/>
      </geometry>
    </visual>
    <collision>
      <origin rpy="0 0 0" xyz="0 0 0"/>
      <geometry>
        <sphere radius="0.019999999999999997"/>
      </geometry>
    </collision>
    <inertial>
      <mass value="0.5"/>
      <inertia ixx="7.999999999999997e-05" ixy="0.0" ixz="0.0" iyy="7.999999999999997e-05" iyz="0.0" izz="7.999999999999997e-05"/>
    </inertial>
  </link>
  <!-- joint: parent_base -> wheel -->
  <joint name="right_leg_base_to_right_back_wheel" type="continuous">
    <origin rpy="-1.57 0 0" xyz="-0.12 0 -0.06"/>
    <parent link="right_leg_base"/>
    <child link="right_back_wheel"/>
    <axis xyz="0 0 1"/>
  </joint>
  <!-- link: wheel -->
  <link name="right_back_wheel">
    <origin rpy="-1.570796325 0 0" xyz="0 0 0"/>
    <visual>
      <origin rpy="0 0 0" xyz="0 0 0"/>
      <geometry>
        <sphere radius="0.019999999999999997"/>
      </geometry>
    </visual>
    <collision>
      <origin rpy="0 0 0" xyz="0 0 0"/>
      <geometry>
        <sphere radius="0.019999999999999997"/>
      </geometry>
    </collision>
    <inertial>
      <mass value="0.5"/>
      <inertia ixx="7.999999999999997e-05" ixy="0.0" ixz="0.0" iyy="7.999999999999997e-05" iyz="0.0" izz="7.999999999999997e-05"/>
    </inertial>
  </link>
  <joint name="base_link_to_imu" type="fixed">
    <origin rpy="0 0 0" xyz="0.0 0.0 0.055"/>
    <parent link="base_link"/>
    <child link="imu"/>
  </joint>
  <link name="imu">
    <visual>
      <geometry>
        <box size="0.2 0.2 0.05"/>
      </geometry>
    </visual>
    <collision>
      <geometry>
        <box size="0.2 0.2 0.05"/>
      </geometry>
    </collision>
    <inertial>
      <mass value="1e-5"/>
      <origin rpy="0 0 0" xyz="0 0 0"/>
      <inertia ixx="1e-6" ixy="0" ixz="0" iyy="1e-6" iyz="0" izz="1e-6"/>
    </inertial>
  </link>
  <gazebo reference="imu">
    <gravity>true</gravity>
    <sensor name="imu_sensor" type="imu">
      <always_on>true</always_on>
      <update_rate>100</update_rate>
      <visualize>true</visualize>
      <pose>0 0 0 0 0 0</pose>
      <plugin filename="libgazebo_ros_imu_sensor.so" name="imu_plugin">
        <ros>
          <!-- publish to /imu/data -->
          <!-- <namespace>/bno055</namespace> -->
          <remapping>~/out:=imu</remapping>
        </ros>
        <topicName>imu</topicName>
        <bodyName>imu</bodyName>
        <updateRateHZ>50.0</updateRateHZ>
        <gaussianNoise>0.005</gaussianNoise>
        <xyzOffset>0 0 0</xyzOffset>
        <rpyOffset>0 0 0</rpyOffset>
        <frameName>imu</frameName>
      </plugin>
    </sensor>
  </gazebo>
  <!-- 
  <gazebo reference="imu_link">
    <sensor name="imu_sensor" type="imu">
      <plugin filename="libgazebo_ros_imu_sensor.so" name="imu_plugin">
        <ros>
          <namespace>/bno055</namespace>
          <remapping>~/out:=imu</remapping>
        </ros>
        <initial_orientation_as_reference>false</initial_orientation_as_reference>
      </plugin>
      <always_on>true</always_on>
      <update_rate>100</update_rate>
      <visualize>true</visualize>
     <imu>
     	<angular_velocity>
     	  <x>
     	    <noise type="gaussian">
              <mean>0.0</mean>
              <stddev>2e-4</stddev>
              <bias_mean>0.0000075</bias_mean>
              <bias_stddev>0.0000008</bias_stddev>
            </noise>
          </x>
          <y>
            <noise type="gaussian">
              <mean>0.0</mean>
              <stddev>2e-4</stddev>
              <bias_mean>0.0000075</bias_mean>
              <bias_stddev>0.0000008</bias_stddev>
            </noise>
          </y>
          <z>
            <noise type="gaussian">
              <mean>0.0</mean>
              <stddev>2e-4</stddev>
              <bias_mean>0.0000075</bias_mean>
              <bias_stddev>0.0000008</bias_stddev>
            </noise>
          </z>
        </angular_velocity>
        <linear_acceleration>
          <x>
            <noise type="gaussian">
              <mean>0.0</mean>
              <stddev>1.7e-2</stddev>
              <bias_mean>0.1</bias_mean>
              <bias_stddev>0.001</bias_stddev>
            </noise>
          </x>
          <y>
            <noise type="gaussian">
              <mean>0.0</mean>
              <stddev>1.7e-2</stddev>
              <bias_mean>0.1</bias_mean>
              <bias_stddev>0.001</bias_stddev>
            </noise>
          </y>
          <z>
            <noise type="gaussian">
              <mean>0.0</mean>
              <stddev>1.7e-2</stddev>
              <bias_mean>0.1</bias_mean>
              <bias_stddev>0.001</bias_stddev>
            </noise>
          </z>
        </linear_acceleration>
      </imu>
    </sensor>
  </gazebo>
   -->
  <gazebo>
    <plugin filename="libgazebo_ros_diff_drive.so" name="diff_drive">
      <ros>
        <!-- <namespace>/robot</namespace> -->
        <!-- <remapping>cmd_vel:=cmd_vel</remapping> -->
        <!-- <remapping>odom:=odom</remapping> -->
      </ros>
      <update_rate>30</update_rate>
      <command_topic>cmd_vel</command_topic>
      <!-- wheels -->
      <left_joint>left_leg_base_to_left_center_wheel</left_joint>
      <right_joint>right_leg_base_to_right_center_wheel</right_joint>
      <!-- kinematics -->
      <wheel_separation>0.4</wheel_separation>
      <wheel_diameter>0.04</wheel_diameter>
      <!-- limits -->
      <max_wheel_torque>20</max_wheel_torque>
      <max_wheel_acceleration>1.0</max_wheel_acceleration>
      <!-- output -->
      <publish_odom>true</publish_odom>
      <publish_odom_tf>true</publish_odom_tf>
      <publish_wheel_tf>false</publish_wheel_tf>
      <odometry_topic>odom</odometry_topic>
      <odometry_frame>odom</odometry_frame>
      <robot_base_frame>base_footprint</robot_base_frame>
    </plugin>
  </gazebo>
  <!-- <plugin name="joint_state" filename="libgazebo_ros_joint_state_publisher.so">
      <ros>
        <remapping>~/out:=joint_states</remapping>
      </ros>
      <update_rate>30</update_rate>
      <joint_name>left_leg_base_to_left_center_wheel</joint_name>
      <joint_name>right_leg_base_to_right_center_wheel</joint_name>
      <joint_name>joint_base_footprint_to_base</joint_name>
    </plugin>   -->
  <gazebo reference="base_scan">
    <sensor name="base_scan" type="ray">
      <ray>
        <scan>
          <horizontal>
            <samples>180</samples>
            <resolution>1.0</resolution>
            <min_angle>-1.57</min_angle>
            <max_angle>1.57</max_angle>
          </horizontal>
        </scan>
        <range>
          <min>0.5</min>
          <max>30.0</max>
          <resolution>0.015000</resolution>
        </range>
      </ray>
      <always_on>true</always_on>
      <update_rate>100.0</update_rate>
      <visualize>true</visualize>
      <plugin filename="libgazebo_ros_ray_sensor.so" name="laserscan">
        <ros>
          <remapping>~/out:=scan</remapping>
        </ros>
        <output_type>sensor_msgs/LaserScan</output_type>
        <!-- <frame_name>base_scan</frame_name> -->
      </plugin>
    </sensor>
  </gazebo>
  <gazebo reference="head_box">
    <!-- <sensor name="sensor_${reference}" type="camera">

        <camera>
          <horizontal_fov>1.3962634</horizontal_fov>
          <image>
            <width>800</width>
            <height>800</height>
            <format>R8G8B8</format>
          </image>
          <clip>
            <near>0.04</near>
            <far>300</far>
          </clip>
        </camera>

        <plugin name="${reference}_controller" filename="libgazebo_ros_camera.so">
          <alwaysOn>true</alwaysOn>
          <updateRate>0.0</updateRate>
          <cameraName>camera_${reference}</cameraName>
          <imageTopicName>image_raw</imageTopicName>
          <cameraInfoTopicName>camera_info</cameraInfoTopicName>
          <frameName>${reference}</frameName>
          <hackBaseline>0.07</hackBaseline>
          <distortionK1>0.0</distortionK1>
          <distortionK2>0.0</distortionK2>
          <distortionK3>0.0</distortionK3>
          <distortionT1>0.0</distortionT1>
          <distortionT2>0.0</distortionT2>
        </plugin>

      </sensor> -->
    <sensor name="camera1" type="camera">
      <update_rate>60</update_rate>
      <visualize>true</visualize>
      <camera name="head">
        <horizontal_fov>1.3962634</horizontal_fov>
        <image>
          <width>640</width>
          <height>480</height>
          <format>R8G8B8</format>
        </image>
        <clip>
          <near>0.02</near>
          <far>300</far>
        </clip>
        <noise>
          <type>gaussian</type>
          <mean>0.0</mean>
          <stddev>0.007</stddev>
        </noise>
      </camera>
      <plugin filename="libgazebo_ros_camera.so" name="camera_controller">
        <ros>
          <namespace>robot</namespace>
          <!-- TODO(louise) Remapping not working due to https://github.com/ros-perception/image_common/issues/93 -->
          <!-- <remapping>image_raw:=image_demo</remapping> -->
          <!-- <remapping>camera_info:=camera_info_demo</remapping> -->
        </ros>
        <!-- camera_name>omit so it defaults to sensor name</camera_name-->
        <!-- frame_name>omit so it defaults to link name</frame_name-->
      </plugin>
    </sensor>
  </gazebo>
</robot>